Watching for file changes with StatReloader
Watching for file changes with StatReloader
"GET / HTTP/1.1" 200 16351
"GET /static/admin/css/fonts.css HTTP/1.1" 200 423
"GET /static/admin/fonts/Roboto-Bold-webfont.woff HTTP/1.1" 200 86184
"GET /static/admin/fonts/Roboto-Regular-webfont.woff HTTP/1.1" 200 85876
"GET /static/admin/fonts/Roboto-Light-webfont.woff HTTP/1.1" 200 85692
Not Found: /favicon.ico
"GET /favicon.ico HTTP/1.1" 404 1978
/home/sandeep/simfoni_task/simfoni_task/urls.py changed, reloading.
Watching for file changes with StatReloader
/home/sandeep/simfoni_task/suppliers/models.py changed, reloading.
Watching for file changes with StatReloader
/home/sandeep/simfoni_task/suppliers/models.py changed, reloading.
Watching for file changes with StatReloader
/home/sandeep/simfoni_task/suppliers/models.py changed, reloading.
Watching for file changes with StatReloader
/home/sandeep/simfoni_task/suppliers/models.py changed, reloading.
Watching for file changes with StatReloader
/home/sandeep/simfoni_task/suppliers/models.py changed, reloading.
Watching for file changes with StatReloader
/home/sandeep/simfoni_task/suppliers/models.py changed, reloading.
Watching for file changes with StatReloader
/home/sandeep/simfoni_task/suppliers/models.py changed, reloading.
Watching for file changes with StatReloader
/home/sandeep/simfoni_task/suppliers/models.py changed, reloading.
Watching for file changes with StatReloader
/home/sandeep/simfoni_task/suppliers/models.py changed, reloading.
Watching for file changes with StatReloader
/home/sandeep/simfoni_task/suppliers/models.py changed, reloading.
Watching for file changes with StatReloader
/home/sandeep/simfoni_task/suppliers/models.py changed, reloading.
Watching for file changes with StatReloader
/home/sandeep/simfoni_task/suppliers/models.py changed, reloading.
Watching for file changes with StatReloader
/home/sandeep/simfoni_task/suppliers/models.py changed, reloading.
Watching for file changes with StatReloader
/home/sandeep/simfoni_task/suppliers/models.py changed, reloading.
Watching for file changes with StatReloader
/home/sandeep/simfoni_task/suppliers/models.py changed, reloading.
Watching for file changes with StatReloader
/home/sandeep/simfoni_task/suppliers/models.py changed, reloading.
Watching for file changes with StatReloader
/home/sandeep/simfoni_task/suppliers/models.py changed, reloading.
Watching for file changes with StatReloader
/home/sandeep/simfoni_task/suppliers/models.py changed, reloading.
Watching for file changes with StatReloader
/home/sandeep/simfoni_task/suppliers/models.py changed, reloading.
Watching for file changes with StatReloader
Watching for file changes with StatReloader
Watching for file changes with StatReloader
Watching for file changes with StatReloader
/home/sandeep/simfoni_task/suppliers/views.py changed, reloading.
Watching for file changes with StatReloader
/home/sandeep/simfoni_task/suppliers/urls.py changed, reloading.
Watching for file changes with StatReloader
Not Found: /
"GET / HTTP/1.1" 404 2037
/home/sandeep/simfoni_task/simfoni_task/urls.py changed, reloading.
Watching for file changes with StatReloader
Watching for file changes with StatReloader
Internal Server Error: /
Traceback (most recent call last):
  File "/home/sandeep/.local/share/virtualenvs/simfoni_env/lib/python3.7/site-packages/django/core/handlers/exception.py", line 47, in inner
    response = get_response(request)
  File "/home/sandeep/.local/share/virtualenvs/simfoni_env/lib/python3.7/site-packages/django/core/handlers/base.py", line 204, in _get_response
    response = response.render()
  File "/home/sandeep/.local/share/virtualenvs/simfoni_env/lib/python3.7/site-packages/django/template/response.py", line 105, in render
    self.content = self.rendered_content
  File "/home/sandeep/.local/share/virtualenvs/simfoni_env/lib/python3.7/site-packages/rest_framework/response.py", line 70, in rendered_content
    ret = renderer.render(self.data, accepted_media_type, context)
  File "/home/sandeep/.local/share/virtualenvs/simfoni_env/lib/python3.7/site-packages/drf_yasg/renderers.py", line 73, in render
    return render_to_string(self.template, renderer_context, renderer_context['request'])
  File "/home/sandeep/.local/share/virtualenvs/simfoni_env/lib/python3.7/site-packages/django/template/loader.py", line 61, in render_to_string
    template = get_template(template_name, using=using)
  File "/home/sandeep/.local/share/virtualenvs/simfoni_env/lib/python3.7/site-packages/django/template/loader.py", line 19, in get_template
    raise TemplateDoesNotExist(template_name, chain=chain)
django.template.exceptions.TemplateDoesNotExist: drf-yasg/swagger-ui.html
"GET / HTTP/1.1" 500 98016
Watching for file changes with StatReloader
Internal Server Error: /
Traceback (most recent call last):
  File "/home/sandeep/.local/share/virtualenvs/simfoni_env/lib/python3.7/site-packages/django/core/handlers/exception.py", line 47, in inner
    response = get_response(request)
  File "/home/sandeep/.local/share/virtualenvs/simfoni_env/lib/python3.7/site-packages/django/core/handlers/base.py", line 204, in _get_response
    response = response.render()
  File "/home/sandeep/.local/share/virtualenvs/simfoni_env/lib/python3.7/site-packages/django/template/response.py", line 105, in render
    self.content = self.rendered_content
  File "/home/sandeep/.local/share/virtualenvs/simfoni_env/lib/python3.7/site-packages/rest_framework/response.py", line 70, in rendered_content
    ret = renderer.render(self.data, accepted_media_type, context)
  File "/home/sandeep/.local/share/virtualenvs/simfoni_env/lib/python3.7/site-packages/drf_yasg/renderers.py", line 73, in render
    return render_to_string(self.template, renderer_context, renderer_context['request'])
  File "/home/sandeep/.local/share/virtualenvs/simfoni_env/lib/python3.7/site-packages/django/template/loader.py", line 61, in render_to_string
    template = get_template(template_name, using=using)
  File "/home/sandeep/.local/share/virtualenvs/simfoni_env/lib/python3.7/site-packages/django/template/loader.py", line 19, in get_template
    raise TemplateDoesNotExist(template_name, chain=chain)
django.template.exceptions.TemplateDoesNotExist: drf-yasg/swagger-ui.html
"GET / HTTP/1.1" 500 98016
Internal Server Error: /
Traceback (most recent call last):
  File "/home/sandeep/.local/share/virtualenvs/simfoni_env/lib/python3.7/site-packages/django/core/handlers/exception.py", line 47, in inner
    response = get_response(request)
  File "/home/sandeep/.local/share/virtualenvs/simfoni_env/lib/python3.7/site-packages/django/core/handlers/base.py", line 204, in _get_response
    response = response.render()
  File "/home/sandeep/.local/share/virtualenvs/simfoni_env/lib/python3.7/site-packages/django/template/response.py", line 105, in render
    self.content = self.rendered_content
  File "/home/sandeep/.local/share/virtualenvs/simfoni_env/lib/python3.7/site-packages/rest_framework/response.py", line 70, in rendered_content
    ret = renderer.render(self.data, accepted_media_type, context)
  File "/home/sandeep/.local/share/virtualenvs/simfoni_env/lib/python3.7/site-packages/drf_yasg/renderers.py", line 73, in render
    return render_to_string(self.template, renderer_context, renderer_context['request'])
  File "/home/sandeep/.local/share/virtualenvs/simfoni_env/lib/python3.7/site-packages/django/template/loader.py", line 61, in render_to_string
    template = get_template(template_name, using=using)
  File "/home/sandeep/.local/share/virtualenvs/simfoni_env/lib/python3.7/site-packages/django/template/loader.py", line 19, in get_template
    raise TemplateDoesNotExist(template_name, chain=chain)
django.template.exceptions.TemplateDoesNotExist: drf-yasg/swagger-ui.html
"GET / HTTP/1.1" 500 98016
Internal Server Error: /
Traceback (most recent call last):
  File "/home/sandeep/.local/share/virtualenvs/simfoni_env/lib/python3.7/site-packages/django/core/handlers/exception.py", line 47, in inner
    response = get_response(request)
  File "/home/sandeep/.local/share/virtualenvs/simfoni_env/lib/python3.7/site-packages/django/core/handlers/base.py", line 204, in _get_response
    response = response.render()
  File "/home/sandeep/.local/share/virtualenvs/simfoni_env/lib/python3.7/site-packages/django/template/response.py", line 105, in render
    self.content = self.rendered_content
  File "/home/sandeep/.local/share/virtualenvs/simfoni_env/lib/python3.7/site-packages/rest_framework/response.py", line 70, in rendered_content
    ret = renderer.render(self.data, accepted_media_type, context)
  File "/home/sandeep/.local/share/virtualenvs/simfoni_env/lib/python3.7/site-packages/drf_yasg/renderers.py", line 73, in render
    return render_to_string(self.template, renderer_context, renderer_context['request'])
  File "/home/sandeep/.local/share/virtualenvs/simfoni_env/lib/python3.7/site-packages/django/template/loader.py", line 61, in render_to_string
    template = get_template(template_name, using=using)
  File "/home/sandeep/.local/share/virtualenvs/simfoni_env/lib/python3.7/site-packages/django/template/loader.py", line 19, in get_template
    raise TemplateDoesNotExist(template_name, chain=chain)
django.template.exceptions.TemplateDoesNotExist: drf-yasg/swagger-ui.html
"GET / HTTP/1.1" 500 98016
/home/sandeep/simfoni_task/simfoni_task/settings.py changed, reloading.
Watching for file changes with StatReloader
Internal Server Error: /
Traceback (most recent call last):
  File "/home/sandeep/.local/share/virtualenvs/simfoni_env/lib/python3.7/site-packages/django/core/handlers/exception.py", line 47, in inner
    response = get_response(request)
  File "/home/sandeep/.local/share/virtualenvs/simfoni_env/lib/python3.7/site-packages/django/core/handlers/base.py", line 204, in _get_response
    response = response.render()
  File "/home/sandeep/.local/share/virtualenvs/simfoni_env/lib/python3.7/site-packages/django/template/response.py", line 105, in render
    self.content = self.rendered_content
  File "/home/sandeep/.local/share/virtualenvs/simfoni_env/lib/python3.7/site-packages/rest_framework/response.py", line 70, in rendered_content
    ret = renderer.render(self.data, accepted_media_type, context)
  File "/home/sandeep/.local/share/virtualenvs/simfoni_env/lib/python3.7/site-packages/drf_yasg/renderers.py", line 73, in render
    return render_to_string(self.template, renderer_context, renderer_context['request'])
  File "/home/sandeep/.local/share/virtualenvs/simfoni_env/lib/python3.7/site-packages/django/template/loader.py", line 61, in render_to_string
    template = get_template(template_name, using=using)
  File "/home/sandeep/.local/share/virtualenvs/simfoni_env/lib/python3.7/site-packages/django/template/loader.py", line 19, in get_template
    raise TemplateDoesNotExist(template_name, chain=chain)
django.template.exceptions.TemplateDoesNotExist: drf-yasg/swagger-ui.html
"GET / HTTP/1.1" 500 98029
Internal Server Error: /
Traceback (most recent call last):
  File "/home/sandeep/.local/share/virtualenvs/simfoni_env/lib/python3.7/site-packages/django/core/handlers/exception.py", line 47, in inner
    response = get_response(request)
  File "/home/sandeep/.local/share/virtualenvs/simfoni_env/lib/python3.7/site-packages/django/core/handlers/base.py", line 204, in _get_response
    response = response.render()
  File "/home/sandeep/.local/share/virtualenvs/simfoni_env/lib/python3.7/site-packages/django/template/response.py", line 105, in render
    self.content = self.rendered_content
  File "/home/sandeep/.local/share/virtualenvs/simfoni_env/lib/python3.7/site-packages/rest_framework/response.py", line 70, in rendered_content
    ret = renderer.render(self.data, accepted_media_type, context)
  File "/home/sandeep/.local/share/virtualenvs/simfoni_env/lib/python3.7/site-packages/drf_yasg/renderers.py", line 73, in render
    return render_to_string(self.template, renderer_context, renderer_context['request'])
  File "/home/sandeep/.local/share/virtualenvs/simfoni_env/lib/python3.7/site-packages/django/template/loader.py", line 61, in render_to_string
    template = get_template(template_name, using=using)
  File "/home/sandeep/.local/share/virtualenvs/simfoni_env/lib/python3.7/site-packages/django/template/loader.py", line 19, in get_template
    raise TemplateDoesNotExist(template_name, chain=chain)
django.template.exceptions.TemplateDoesNotExist: drf-yasg/swagger-ui.html
"GET / HTTP/1.1" 500 98029
Internal Server Error: /
Traceback (most recent call last):
  File "/home/sandeep/.local/share/virtualenvs/simfoni_env/lib/python3.7/site-packages/django/core/handlers/exception.py", line 47, in inner
    response = get_response(request)
  File "/home/sandeep/.local/share/virtualenvs/simfoni_env/lib/python3.7/site-packages/django/core/handlers/base.py", line 204, in _get_response
    response = response.render()
  File "/home/sandeep/.local/share/virtualenvs/simfoni_env/lib/python3.7/site-packages/django/template/response.py", line 105, in render
    self.content = self.rendered_content
  File "/home/sandeep/.local/share/virtualenvs/simfoni_env/lib/python3.7/site-packages/rest_framework/response.py", line 70, in rendered_content
    ret = renderer.render(self.data, accepted_media_type, context)
  File "/home/sandeep/.local/share/virtualenvs/simfoni_env/lib/python3.7/site-packages/drf_yasg/renderers.py", line 73, in render
    return render_to_string(self.template, renderer_context, renderer_context['request'])
  File "/home/sandeep/.local/share/virtualenvs/simfoni_env/lib/python3.7/site-packages/django/template/loader.py", line 61, in render_to_string
    template = get_template(template_name, using=using)
  File "/home/sandeep/.local/share/virtualenvs/simfoni_env/lib/python3.7/site-packages/django/template/loader.py", line 19, in get_template
    raise TemplateDoesNotExist(template_name, chain=chain)
django.template.exceptions.TemplateDoesNotExist: drf-yasg/swagger-ui.html
"GET / HTTP/1.1" 500 98029
/home/sandeep/simfoni_task/simfoni_task/settings.py changed, reloading.
Watching for file changes with StatReloader
/home/sandeep/simfoni_task/simfoni_task/settings.py changed, reloading.
Watching for file changes with StatReloader
Internal Server Error: /
Traceback (most recent call last):
  File "/home/sandeep/.local/share/virtualenvs/simfoni_env/lib/python3.7/site-packages/django/core/handlers/exception.py", line 47, in inner
    response = get_response(request)
  File "/home/sandeep/.local/share/virtualenvs/simfoni_env/lib/python3.7/site-packages/django/core/handlers/base.py", line 204, in _get_response
    response = response.render()
  File "/home/sandeep/.local/share/virtualenvs/simfoni_env/lib/python3.7/site-packages/django/template/response.py", line 105, in render
    self.content = self.rendered_content
  File "/home/sandeep/.local/share/virtualenvs/simfoni_env/lib/python3.7/site-packages/rest_framework/response.py", line 70, in rendered_content
    ret = renderer.render(self.data, accepted_media_type, context)
  File "/home/sandeep/.local/share/virtualenvs/simfoni_env/lib/python3.7/site-packages/drf_yasg/renderers.py", line 73, in render
    return render_to_string(self.template, renderer_context, renderer_context['request'])
  File "/home/sandeep/.local/share/virtualenvs/simfoni_env/lib/python3.7/site-packages/django/template/loader.py", line 61, in render_to_string
    template = get_template(template_name, using=using)
  File "/home/sandeep/.local/share/virtualenvs/simfoni_env/lib/python3.7/site-packages/django/template/loader.py", line 19, in get_template
    raise TemplateDoesNotExist(template_name, chain=chain)
django.template.exceptions.TemplateDoesNotExist: drf-yasg/swagger-ui.html
"GET / HTTP/1.1" 500 98029
Internal Server Error: /
Traceback (most recent call last):
  File "/home/sandeep/.local/share/virtualenvs/simfoni_env/lib/python3.7/site-packages/django/core/handlers/exception.py", line 47, in inner
    response = get_response(request)
  File "/home/sandeep/.local/share/virtualenvs/simfoni_env/lib/python3.7/site-packages/django/core/handlers/base.py", line 204, in _get_response
    response = response.render()
  File "/home/sandeep/.local/share/virtualenvs/simfoni_env/lib/python3.7/site-packages/django/template/response.py", line 105, in render
    self.content = self.rendered_content
  File "/home/sandeep/.local/share/virtualenvs/simfoni_env/lib/python3.7/site-packages/rest_framework/response.py", line 70, in rendered_content
    ret = renderer.render(self.data, accepted_media_type, context)
  File "/home/sandeep/.local/share/virtualenvs/simfoni_env/lib/python3.7/site-packages/drf_yasg/renderers.py", line 73, in render
    return render_to_string(self.template, renderer_context, renderer_context['request'])
  File "/home/sandeep/.local/share/virtualenvs/simfoni_env/lib/python3.7/site-packages/django/template/loader.py", line 61, in render_to_string
    template = get_template(template_name, using=using)
  File "/home/sandeep/.local/share/virtualenvs/simfoni_env/lib/python3.7/site-packages/django/template/loader.py", line 19, in get_template
    raise TemplateDoesNotExist(template_name, chain=chain)
django.template.exceptions.TemplateDoesNotExist: drf-yasg/swagger-ui.html
"GET / HTTP/1.1" 500 98029
Internal Server Error: /
Traceback (most recent call last):
  File "/home/sandeep/.local/share/virtualenvs/simfoni_env/lib/python3.7/site-packages/django/core/handlers/exception.py", line 47, in inner
    response = get_response(request)
  File "/home/sandeep/.local/share/virtualenvs/simfoni_env/lib/python3.7/site-packages/django/core/handlers/base.py", line 204, in _get_response
    response = response.render()
  File "/home/sandeep/.local/share/virtualenvs/simfoni_env/lib/python3.7/site-packages/django/template/response.py", line 105, in render
    self.content = self.rendered_content
  File "/home/sandeep/.local/share/virtualenvs/simfoni_env/lib/python3.7/site-packages/rest_framework/response.py", line 70, in rendered_content
    ret = renderer.render(self.data, accepted_media_type, context)
  File "/home/sandeep/.local/share/virtualenvs/simfoni_env/lib/python3.7/site-packages/drf_yasg/renderers.py", line 73, in render
    return render_to_string(self.template, renderer_context, renderer_context['request'])
  File "/home/sandeep/.local/share/virtualenvs/simfoni_env/lib/python3.7/site-packages/django/template/loader.py", line 61, in render_to_string
    template = get_template(template_name, using=using)
  File "/home/sandeep/.local/share/virtualenvs/simfoni_env/lib/python3.7/site-packages/django/template/loader.py", line 19, in get_template
    raise TemplateDoesNotExist(template_name, chain=chain)
django.template.exceptions.TemplateDoesNotExist: drf-yasg/swagger-ui.html
"GET / HTTP/1.1" 500 98029
/home/sandeep/simfoni_task/simfoni_task/settings.py changed, reloading.
Watching for file changes with StatReloader
/home/sandeep/simfoni_task/simfoni_task/settings.py changed, reloading.
Watching for file changes with StatReloader
"GET / HTTP/1.1" 200 2233
"GET /static/drf-yasg/style.css HTTP/1.1" 200 1047
"GET /static/drf-yasg/swagger-ui-dist/swagger-ui.css HTTP/1.1" 200 143074
"GET /static/drf-yasg/swagger-ui-init.js HTTP/1.1" 200 14715
"GET /static/drf-yasg/swagger-ui-dist/swagger-ui-bundle.js HTTP/1.1" 200 1038857
"GET /static/drf-yasg/swagger-ui-dist/swagger-ui-standalone-preset.js HTTP/1.1" 200 329649
"GET /static/drf-yasg/insQ.min.js HTTP/1.1" 200 2093
"GET /static/drf-yasg/immutable.min.js HTTP/1.1" 200 56904
"GET /static/drf-yasg/url-polyfill.min.js HTTP/1.1" 200 6092
"GET /?format=openapi HTTP/1.1" 200 3062
"GET /static/drf-yasg/swagger-ui-dist/favicon-32x32.png HTTP/1.1" 200 628
/home/sandeep/simfoni_task/simfoni_task/urls.py changed, reloading.
Watching for file changes with StatReloader
"GET / HTTP/1.1" 200 2236
"GET /?format=openapi HTTP/1.1" 200 3065
"GET /static/drf-yasg/swagger-ui-dist/favicon-32x32.png HTTP/1.1" 200 628
/home/sandeep/simfoni_task/simfoni_task/urls.py changed, reloading.
Watching for file changes with StatReloader
/home/sandeep/simfoni_task/suppliers/serializers.py changed, reloading.
Watching for file changes with StatReloader
Not Found: /api/v1/api/suppliers/register/
"POST /api/v1/api/suppliers/register/ HTTP/1.1" 404 2403
Internal Server Error: /api/suppliers/register/
Traceback (most recent call last):
  File "/home/sandeep/.local/share/virtualenvs/simfoni_env/lib/python3.7/site-packages/rest_framework/serializers.py", line 939, in create
    instance = ModelClass._default_manager.create(**validated_data)
  File "/home/sandeep/.local/share/virtualenvs/simfoni_env/lib/python3.7/site-packages/django/db/models/manager.py", line 85, in manager_method
    return getattr(self.get_queryset(), name)(*args, **kwargs)
  File "/home/sandeep/.local/share/virtualenvs/simfoni_env/lib/python3.7/site-packages/django/db/models/query.py", line 445, in create
    obj = self.model(**kwargs)
  File "/home/sandeep/.local/share/virtualenvs/simfoni_env/lib/python3.7/site-packages/django/db/models/base.py", line 501, in __init__
    raise TypeError("%s() got an unexpected keyword argument '%s'" % (cls.__name__, kwarg))
TypeError: Supplier() got an unexpected keyword argument 'password'

During handling of the above exception, another exception occurred:

Traceback (most recent call last):
  File "/home/sandeep/.local/share/virtualenvs/simfoni_env/lib/python3.7/site-packages/django/core/handlers/exception.py", line 47, in inner
    response = get_response(request)
  File "/home/sandeep/.local/share/virtualenvs/simfoni_env/lib/python3.7/site-packages/django/core/handlers/base.py", line 181, in _get_response
    response = wrapped_callback(request, *callback_args, **callback_kwargs)
  File "/home/sandeep/.local/share/virtualenvs/simfoni_env/lib/python3.7/site-packages/django/views/decorators/csrf.py", line 54, in wrapped_view
    return view_func(*args, **kwargs)
  File "/home/sandeep/.local/share/virtualenvs/simfoni_env/lib/python3.7/site-packages/django/views/generic/base.py", line 70, in view
    return self.dispatch(request, *args, **kwargs)
  File "/home/sandeep/.local/share/virtualenvs/simfoni_env/lib/python3.7/site-packages/rest_framework/views.py", line 509, in dispatch
    response = self.handle_exception(exc)
  File "/home/sandeep/.local/share/virtualenvs/simfoni_env/lib/python3.7/site-packages/rest_framework/views.py", line 469, in handle_exception
    self.raise_uncaught_exception(exc)
  File "/home/sandeep/.local/share/virtualenvs/simfoni_env/lib/python3.7/site-packages/rest_framework/views.py", line 480, in raise_uncaught_exception
    raise exc
  File "/home/sandeep/.local/share/virtualenvs/simfoni_env/lib/python3.7/site-packages/rest_framework/views.py", line 506, in dispatch
    response = handler(request, *args, **kwargs)
  File "/home/sandeep/.local/share/virtualenvs/simfoni_env/lib/python3.7/site-packages/rest_framework/generics.py", line 190, in post
    return self.create(request, *args, **kwargs)
  File "/home/sandeep/.local/share/virtualenvs/simfoni_env/lib/python3.7/site-packages/rest_framework/mixins.py", line 19, in create
    self.perform_create(serializer)
  File "/home/sandeep/.local/share/virtualenvs/simfoni_env/lib/python3.7/site-packages/rest_framework/mixins.py", line 24, in perform_create
    serializer.save()
  File "/home/sandeep/.local/share/virtualenvs/simfoni_env/lib/python3.7/site-packages/rest_framework/serializers.py", line 205, in save
    self.instance = self.create(validated_data)
  File "/home/sandeep/.local/share/virtualenvs/simfoni_env/lib/python3.7/site-packages/rest_framework/serializers.py", line 958, in create
    raise TypeError(msg)
TypeError: Got a `TypeError` when calling `Supplier.objects.create()`. This may be because you have a writable field on the serializer class that is not a valid argument to `Supplier.objects.create()`. You may need to make the field read-only, or override the RegisterSupplierSerializer.create() method to handle this correctly.
Original exception was:
 Traceback (most recent call last):
  File "/home/sandeep/.local/share/virtualenvs/simfoni_env/lib/python3.7/site-packages/rest_framework/serializers.py", line 939, in create
    instance = ModelClass._default_manager.create(**validated_data)
  File "/home/sandeep/.local/share/virtualenvs/simfoni_env/lib/python3.7/site-packages/django/db/models/manager.py", line 85, in manager_method
    return getattr(self.get_queryset(), name)(*args, **kwargs)
  File "/home/sandeep/.local/share/virtualenvs/simfoni_env/lib/python3.7/site-packages/django/db/models/query.py", line 445, in create
    obj = self.model(**kwargs)
  File "/home/sandeep/.local/share/virtualenvs/simfoni_env/lib/python3.7/site-packages/django/db/models/base.py", line 501, in __init__
    raise TypeError("%s() got an unexpected keyword argument '%s'" % (cls.__name__, kwarg))
TypeError: Supplier() got an unexpected keyword argument 'password'

"POST /api/suppliers/register/ HTTP/1.1" 500 161239
/home/sandeep/simfoni_task/suppliers/serializers.py changed, reloading.
Watching for file changes with StatReloader
/home/sandeep/simfoni_task/suppliers/serializers.py changed, reloading.
Watching for file changes with StatReloader
Internal Server Error: /api/suppliers/register/
Traceback (most recent call last):
  File "/home/sandeep/.local/share/virtualenvs/simfoni_env/lib/python3.7/site-packages/django/core/handlers/exception.py", line 47, in inner
    response = get_response(request)
  File "/home/sandeep/.local/share/virtualenvs/simfoni_env/lib/python3.7/site-packages/django/core/handlers/base.py", line 181, in _get_response
    response = wrapped_callback(request, *callback_args, **callback_kwargs)
  File "/home/sandeep/.local/share/virtualenvs/simfoni_env/lib/python3.7/site-packages/django/views/decorators/csrf.py", line 54, in wrapped_view
    return view_func(*args, **kwargs)
  File "/home/sandeep/.local/share/virtualenvs/simfoni_env/lib/python3.7/site-packages/django/views/generic/base.py", line 70, in view
    return self.dispatch(request, *args, **kwargs)
  File "/home/sandeep/.local/share/virtualenvs/simfoni_env/lib/python3.7/site-packages/rest_framework/views.py", line 509, in dispatch
    response = self.handle_exception(exc)
  File "/home/sandeep/.local/share/virtualenvs/simfoni_env/lib/python3.7/site-packages/rest_framework/views.py", line 469, in handle_exception
    self.raise_uncaught_exception(exc)
  File "/home/sandeep/.local/share/virtualenvs/simfoni_env/lib/python3.7/site-packages/rest_framework/views.py", line 480, in raise_uncaught_exception
    raise exc
  File "/home/sandeep/.local/share/virtualenvs/simfoni_env/lib/python3.7/site-packages/rest_framework/views.py", line 506, in dispatch
    response = handler(request, *args, **kwargs)
  File "/home/sandeep/.local/share/virtualenvs/simfoni_env/lib/python3.7/site-packages/rest_framework/generics.py", line 190, in post
    return self.create(request, *args, **kwargs)
  File "/home/sandeep/.local/share/virtualenvs/simfoni_env/lib/python3.7/site-packages/rest_framework/mixins.py", line 19, in create
    self.perform_create(serializer)
  File "/home/sandeep/.local/share/virtualenvs/simfoni_env/lib/python3.7/site-packages/rest_framework/mixins.py", line 24, in perform_create
    serializer.save()
  File "/home/sandeep/.local/share/virtualenvs/simfoni_env/lib/python3.7/site-packages/rest_framework/serializers.py", line 205, in save
    self.instance = self.create(validated_data)
  File "/home/sandeep/simfoni_task/suppliers/serializers.py", line 19, in create
    return RegisterSupplierSerializer.objects.create(**validated_data)
AttributeError: type object 'RegisterSupplierSerializer' has no attribute 'objects'
"POST /api/suppliers/register/ HTTP/1.1" 500 118440
/home/sandeep/simfoni_task/suppliers/serializers.py changed, reloading.
Watching for file changes with StatReloader
/home/sandeep/simfoni_task/suppliers/serializers.py changed, reloading.
Watching for file changes with StatReloader
Internal Server Error: /api/suppliers/register/
Traceback (most recent call last):
  File "/home/sandeep/.local/share/virtualenvs/simfoni_env/lib/python3.7/site-packages/django/db/backends/utils.py", line 84, in _execute
    return self.cursor.execute(sql, params)
psycopg2.errors.UniqueViolation: duplicate key value violates unique constraint "auth_user_username_key"
DETAIL:  Key (username)=(sandeep@gmail.com) already exists.


The above exception was the direct cause of the following exception:

Traceback (most recent call last):
  File "/home/sandeep/.local/share/virtualenvs/simfoni_env/lib/python3.7/site-packages/django/core/handlers/exception.py", line 47, in inner
    response = get_response(request)
  File "/home/sandeep/.local/share/virtualenvs/simfoni_env/lib/python3.7/site-packages/django/core/handlers/base.py", line 181, in _get_response
    response = wrapped_callback(request, *callback_args, **callback_kwargs)
  File "/home/sandeep/.local/share/virtualenvs/simfoni_env/lib/python3.7/site-packages/django/views/decorators/csrf.py", line 54, in wrapped_view
    return view_func(*args, **kwargs)
  File "/home/sandeep/.local/share/virtualenvs/simfoni_env/lib/python3.7/site-packages/django/views/generic/base.py", line 70, in view
    return self.dispatch(request, *args, **kwargs)
  File "/home/sandeep/.local/share/virtualenvs/simfoni_env/lib/python3.7/site-packages/rest_framework/views.py", line 509, in dispatch
    response = self.handle_exception(exc)
  File "/home/sandeep/.local/share/virtualenvs/simfoni_env/lib/python3.7/site-packages/rest_framework/views.py", line 469, in handle_exception
    self.raise_uncaught_exception(exc)
  File "/home/sandeep/.local/share/virtualenvs/simfoni_env/lib/python3.7/site-packages/rest_framework/views.py", line 480, in raise_uncaught_exception
    raise exc
  File "/home/sandeep/.local/share/virtualenvs/simfoni_env/lib/python3.7/site-packages/rest_framework/views.py", line 506, in dispatch
    response = handler(request, *args, **kwargs)
  File "/home/sandeep/.local/share/virtualenvs/simfoni_env/lib/python3.7/site-packages/rest_framework/generics.py", line 190, in post
    return self.create(request, *args, **kwargs)
  File "/home/sandeep/.local/share/virtualenvs/simfoni_env/lib/python3.7/site-packages/rest_framework/mixins.py", line 19, in create
    self.perform_create(serializer)
  File "/home/sandeep/.local/share/virtualenvs/simfoni_env/lib/python3.7/site-packages/rest_framework/mixins.py", line 24, in perform_create
    serializer.save()
  File "/home/sandeep/.local/share/virtualenvs/simfoni_env/lib/python3.7/site-packages/rest_framework/serializers.py", line 205, in save
    self.instance = self.create(validated_data)
  File "/home/sandeep/simfoni_task/suppliers/serializers.py", line 17, in create
    user = User.objects.create_user(username=username, password=password)
  File "/home/sandeep/.local/share/virtualenvs/simfoni_env/lib/python3.7/site-packages/django/contrib/auth/models.py", line 146, in create_user
    return self._create_user(username, email, password, **extra_fields)
  File "/home/sandeep/.local/share/virtualenvs/simfoni_env/lib/python3.7/site-packages/django/contrib/auth/models.py", line 140, in _create_user
    user.save(using=self._db)
  File "/home/sandeep/.local/share/virtualenvs/simfoni_env/lib/python3.7/site-packages/django/contrib/auth/base_user.py", line 67, in save
    super().save(*args, **kwargs)
  File "/home/sandeep/.local/share/virtualenvs/simfoni_env/lib/python3.7/site-packages/django/db/models/base.py", line 754, in save
    force_update=force_update, update_fields=update_fields)
  File "/home/sandeep/.local/share/virtualenvs/simfoni_env/lib/python3.7/site-packages/django/db/models/base.py", line 792, in save_base
    force_update, using, update_fields,
  File "/home/sandeep/.local/share/virtualenvs/simfoni_env/lib/python3.7/site-packages/django/db/models/base.py", line 895, in _save_table
    results = self._do_insert(cls._base_manager, using, fields, returning_fields, raw)
  File "/home/sandeep/.local/share/virtualenvs/simfoni_env/lib/python3.7/site-packages/django/db/models/base.py", line 935, in _do_insert
    using=using, raw=raw,
  File "/home/sandeep/.local/share/virtualenvs/simfoni_env/lib/python3.7/site-packages/django/db/models/manager.py", line 85, in manager_method
    return getattr(self.get_queryset(), name)(*args, **kwargs)
  File "/home/sandeep/.local/share/virtualenvs/simfoni_env/lib/python3.7/site-packages/django/db/models/query.py", line 1254, in _insert
    return query.get_compiler(using=using).execute_sql(returning_fields)
  File "/home/sandeep/.local/share/virtualenvs/simfoni_env/lib/python3.7/site-packages/django/db/models/sql/compiler.py", line 1397, in execute_sql
    cursor.execute(sql, params)
  File "/home/sandeep/.local/share/virtualenvs/simfoni_env/lib/python3.7/site-packages/django/db/backends/utils.py", line 98, in execute
    return super().execute(sql, params)
  File "/home/sandeep/.local/share/virtualenvs/simfoni_env/lib/python3.7/site-packages/django/db/backends/utils.py", line 66, in execute
    return self._execute_with_wrappers(sql, params, many=False, executor=self._execute)
  File "/home/sandeep/.local/share/virtualenvs/simfoni_env/lib/python3.7/site-packages/django/db/backends/utils.py", line 75, in _execute_with_wrappers
    return executor(sql, params, many, context)
  File "/home/sandeep/.local/share/virtualenvs/simfoni_env/lib/python3.7/site-packages/django/db/backends/utils.py", line 84, in _execute
    return self.cursor.execute(sql, params)
  File "/home/sandeep/.local/share/virtualenvs/simfoni_env/lib/python3.7/site-packages/django/db/utils.py", line 90, in __exit__
    raise dj_exc_value.with_traceback(traceback) from exc_value
  File "/home/sandeep/.local/share/virtualenvs/simfoni_env/lib/python3.7/site-packages/django/db/backends/utils.py", line 84, in _execute
    return self.cursor.execute(sql, params)
django.db.utils.IntegrityError: duplicate key value violates unique constraint "auth_user_username_key"
DETAIL:  Key (username)=(sandeep@gmail.com) already exists.

"POST /api/suppliers/register/ HTTP/1.1" 500 209644
Internal Server Error: /api/suppliers/register/
Traceback (most recent call last):
  File "/home/sandeep/.local/share/virtualenvs/simfoni_env/lib/python3.7/site-packages/rest_framework/fields.py", line 457, in get_attribute
    return get_attribute(instance, self.source_attrs)
  File "/home/sandeep/.local/share/virtualenvs/simfoni_env/lib/python3.7/site-packages/rest_framework/fields.py", line 97, in get_attribute
    instance = getattr(instance, attr)
AttributeError: 'Supplier' object has no attribute 'password'

During handling of the above exception, another exception occurred:

Traceback (most recent call last):
  File "/home/sandeep/.local/share/virtualenvs/simfoni_env/lib/python3.7/site-packages/django/core/handlers/exception.py", line 47, in inner
    response = get_response(request)
  File "/home/sandeep/.local/share/virtualenvs/simfoni_env/lib/python3.7/site-packages/django/core/handlers/base.py", line 181, in _get_response
    response = wrapped_callback(request, *callback_args, **callback_kwargs)
  File "/home/sandeep/.local/share/virtualenvs/simfoni_env/lib/python3.7/site-packages/django/views/decorators/csrf.py", line 54, in wrapped_view
    return view_func(*args, **kwargs)
  File "/home/sandeep/.local/share/virtualenvs/simfoni_env/lib/python3.7/site-packages/django/views/generic/base.py", line 70, in view
    return self.dispatch(request, *args, **kwargs)
  File "/home/sandeep/.local/share/virtualenvs/simfoni_env/lib/python3.7/site-packages/rest_framework/views.py", line 509, in dispatch
    response = self.handle_exception(exc)
  File "/home/sandeep/.local/share/virtualenvs/simfoni_env/lib/python3.7/site-packages/rest_framework/views.py", line 469, in handle_exception
    self.raise_uncaught_exception(exc)
  File "/home/sandeep/.local/share/virtualenvs/simfoni_env/lib/python3.7/site-packages/rest_framework/views.py", line 480, in raise_uncaught_exception
    raise exc
  File "/home/sandeep/.local/share/virtualenvs/simfoni_env/lib/python3.7/site-packages/rest_framework/views.py", line 506, in dispatch
    response = handler(request, *args, **kwargs)
  File "/home/sandeep/.local/share/virtualenvs/simfoni_env/lib/python3.7/site-packages/rest_framework/generics.py", line 190, in post
    return self.create(request, *args, **kwargs)
  File "/home/sandeep/.local/share/virtualenvs/simfoni_env/lib/python3.7/site-packages/rest_framework/mixins.py", line 20, in create
    headers = self.get_success_headers(serializer.data)
  File "/home/sandeep/.local/share/virtualenvs/simfoni_env/lib/python3.7/site-packages/rest_framework/serializers.py", line 548, in data
    ret = super().data
  File "/home/sandeep/.local/share/virtualenvs/simfoni_env/lib/python3.7/site-packages/rest_framework/serializers.py", line 246, in data
    self._data = self.to_representation(self.instance)
  File "/home/sandeep/.local/share/virtualenvs/simfoni_env/lib/python3.7/site-packages/rest_framework/serializers.py", line 502, in to_representation
    attribute = field.get_attribute(instance)
  File "/home/sandeep/.local/share/virtualenvs/simfoni_env/lib/python3.7/site-packages/rest_framework/fields.py", line 490, in get_attribute
    raise type(exc)(msg)
AttributeError: Got AttributeError when attempting to get a value for field `password` on serializer `RegisterSupplierSerializer`.
The serializer field might be named incorrectly and not match any attribute or key on the `Supplier` instance.
Original exception text was: 'Supplier' object has no attribute 'password'.
"POST /api/suppliers/register/ HTTP/1.1" 500 133531
/home/sandeep/simfoni_task/suppliers/serializers.py changed, reloading.
Watching for file changes with StatReloader
Bad Request: /api/suppliers/register/
"POST /api/suppliers/register/ HTTP/1.1" 400 70
/home/sandeep/simfoni_task/suppliers/serializers.py changed, reloading.
Watching for file changes with StatReloader
Internal Server Error: /api/suppliers/register/
Traceback (most recent call last):
  File "/home/sandeep/.local/share/virtualenvs/simfoni_env/lib/python3.7/site-packages/rest_framework/fields.py", line 457, in get_attribute
    return get_attribute(instance, self.source_attrs)
  File "/home/sandeep/.local/share/virtualenvs/simfoni_env/lib/python3.7/site-packages/rest_framework/fields.py", line 97, in get_attribute
    instance = getattr(instance, attr)
AttributeError: 'Supplier' object has no attribute 'password'

During handling of the above exception, another exception occurred:

Traceback (most recent call last):
  File "/home/sandeep/.local/share/virtualenvs/simfoni_env/lib/python3.7/site-packages/django/core/handlers/exception.py", line 47, in inner
    response = get_response(request)
  File "/home/sandeep/.local/share/virtualenvs/simfoni_env/lib/python3.7/site-packages/django/core/handlers/base.py", line 181, in _get_response
    response = wrapped_callback(request, *callback_args, **callback_kwargs)
  File "/home/sandeep/.local/share/virtualenvs/simfoni_env/lib/python3.7/site-packages/django/views/decorators/csrf.py", line 54, in wrapped_view
    return view_func(*args, **kwargs)
  File "/home/sandeep/.local/share/virtualenvs/simfoni_env/lib/python3.7/site-packages/django/views/generic/base.py", line 70, in view
    return self.dispatch(request, *args, **kwargs)
  File "/home/sandeep/.local/share/virtualenvs/simfoni_env/lib/python3.7/site-packages/rest_framework/views.py", line 509, in dispatch
    response = self.handle_exception(exc)
  File "/home/sandeep/.local/share/virtualenvs/simfoni_env/lib/python3.7/site-packages/rest_framework/views.py", line 469, in handle_exception
    self.raise_uncaught_exception(exc)
  File "/home/sandeep/.local/share/virtualenvs/simfoni_env/lib/python3.7/site-packages/rest_framework/views.py", line 480, in raise_uncaught_exception
    raise exc
  File "/home/sandeep/.local/share/virtualenvs/simfoni_env/lib/python3.7/site-packages/rest_framework/views.py", line 506, in dispatch
    response = handler(request, *args, **kwargs)
  File "/home/sandeep/.local/share/virtualenvs/simfoni_env/lib/python3.7/site-packages/rest_framework/generics.py", line 190, in post
    return self.create(request, *args, **kwargs)
  File "/home/sandeep/.local/share/virtualenvs/simfoni_env/lib/python3.7/site-packages/rest_framework/mixins.py", line 20, in create
    headers = self.get_success_headers(serializer.data)
  File "/home/sandeep/.local/share/virtualenvs/simfoni_env/lib/python3.7/site-packages/rest_framework/serializers.py", line 548, in data
    ret = super().data
  File "/home/sandeep/.local/share/virtualenvs/simfoni_env/lib/python3.7/site-packages/rest_framework/serializers.py", line 246, in data
    self._data = self.to_representation(self.instance)
  File "/home/sandeep/.local/share/virtualenvs/simfoni_env/lib/python3.7/site-packages/rest_framework/serializers.py", line 502, in to_representation
    attribute = field.get_attribute(instance)
  File "/home/sandeep/.local/share/virtualenvs/simfoni_env/lib/python3.7/site-packages/rest_framework/fields.py", line 490, in get_attribute
    raise type(exc)(msg)
AttributeError: Got AttributeError when attempting to get a value for field `password` on serializer `RegisterSupplierSerializer`.
The serializer field might be named incorrectly and not match any attribute or key on the `Supplier` instance.
Original exception text was: 'Supplier' object has no attribute 'password'.
"POST /api/suppliers/register/ HTTP/1.1" 500 133531
/home/sandeep/simfoni_task/suppliers/serializers.py changed, reloading.
Watching for file changes with StatReloader
/home/sandeep/simfoni_task/suppliers/serializers.py changed, reloading.
Watching for file changes with StatReloader
Internal Server Error: /api/suppliers/register/
Traceback (most recent call last):
  File "/home/sandeep/.local/share/virtualenvs/simfoni_env/lib/python3.7/site-packages/django/core/handlers/exception.py", line 47, in inner
    response = get_response(request)
  File "/home/sandeep/.local/share/virtualenvs/simfoni_env/lib/python3.7/site-packages/django/core/handlers/base.py", line 181, in _get_response
    response = wrapped_callback(request, *callback_args, **callback_kwargs)
  File "/home/sandeep/.local/share/virtualenvs/simfoni_env/lib/python3.7/site-packages/django/views/decorators/csrf.py", line 54, in wrapped_view
    return view_func(*args, **kwargs)
  File "/home/sandeep/.local/share/virtualenvs/simfoni_env/lib/python3.7/site-packages/django/views/generic/base.py", line 70, in view
    return self.dispatch(request, *args, **kwargs)
  File "/home/sandeep/.local/share/virtualenvs/simfoni_env/lib/python3.7/site-packages/rest_framework/views.py", line 509, in dispatch
    response = self.handle_exception(exc)
  File "/home/sandeep/.local/share/virtualenvs/simfoni_env/lib/python3.7/site-packages/rest_framework/views.py", line 469, in handle_exception
    self.raise_uncaught_exception(exc)
  File "/home/sandeep/.local/share/virtualenvs/simfoni_env/lib/python3.7/site-packages/rest_framework/views.py", line 480, in raise_uncaught_exception
    raise exc
  File "/home/sandeep/.local/share/virtualenvs/simfoni_env/lib/python3.7/site-packages/rest_framework/views.py", line 506, in dispatch
    response = handler(request, *args, **kwargs)
  File "/home/sandeep/.local/share/virtualenvs/simfoni_env/lib/python3.7/site-packages/rest_framework/generics.py", line 190, in post
    return self.create(request, *args, **kwargs)
  File "/home/sandeep/.local/share/virtualenvs/simfoni_env/lib/python3.7/site-packages/rest_framework/mixins.py", line 18, in create
    serializer.is_valid(raise_exception=True)
  File "/home/sandeep/.local/share/virtualenvs/simfoni_env/lib/python3.7/site-packages/rest_framework/serializers.py", line 220, in is_valid
    self._validated_data = self.run_validation(self.initial_data)
  File "/home/sandeep/.local/share/virtualenvs/simfoni_env/lib/python3.7/site-packages/rest_framework/serializers.py", line 419, in run_validation
    value = self.to_internal_value(data)
  File "/home/sandeep/.local/share/virtualenvs/simfoni_env/lib/python3.7/site-packages/rest_framework/serializers.py", line 472, in to_internal_value
    for field in fields:
  File "/home/sandeep/.local/share/virtualenvs/simfoni_env/lib/python3.7/site-packages/rest_framework/serializers.py", line 355, in _writable_fields
    for field in self.fields.values():
  File "/home/sandeep/.local/share/virtualenvs/simfoni_env/lib/python3.7/site-packages/django/utils/functional.py", line 48, in __get__
    res = instance.__dict__[self.name] = self.func(instance)
  File "/home/sandeep/.local/share/virtualenvs/simfoni_env/lib/python3.7/site-packages/rest_framework/serializers.py", line 349, in fields
    for key, value in self.get_fields().items():
  File "/home/sandeep/.local/share/virtualenvs/simfoni_env/lib/python3.7/site-packages/rest_framework/serializers.py", line 1029, in get_fields
    field_names = self.get_field_names(declared_fields, info)
  File "/home/sandeep/.local/share/virtualenvs/simfoni_env/lib/python3.7/site-packages/rest_framework/serializers.py", line 1130, in get_field_names
    serializer_class=self.__class__.__name__
AssertionError: The field 'password' was declared on serializer RegisterSupplierSerializer, but has not been included in the 'fields' option.
"POST /api/suppliers/register/ HTTP/1.1" 500 145912
/home/sandeep/simfoni_task/suppliers/serializers.py changed, reloading.
Watching for file changes with StatReloader
Internal Server Error: /api/suppliers/register/
Traceback (most recent call last):
  File "/home/sandeep/.local/share/virtualenvs/simfoni_env/lib/python3.7/site-packages/django/core/handlers/exception.py", line 47, in inner
    response = get_response(request)
  File "/home/sandeep/.local/share/virtualenvs/simfoni_env/lib/python3.7/site-packages/django/core/handlers/base.py", line 181, in _get_response
    response = wrapped_callback(request, *callback_args, **callback_kwargs)
  File "/home/sandeep/.local/share/virtualenvs/simfoni_env/lib/python3.7/site-packages/django/views/decorators/csrf.py", line 54, in wrapped_view
    return view_func(*args, **kwargs)
  File "/home/sandeep/.local/share/virtualenvs/simfoni_env/lib/python3.7/site-packages/django/views/generic/base.py", line 70, in view
    return self.dispatch(request, *args, **kwargs)
  File "/home/sandeep/.local/share/virtualenvs/simfoni_env/lib/python3.7/site-packages/rest_framework/views.py", line 509, in dispatch
    response = self.handle_exception(exc)
  File "/home/sandeep/.local/share/virtualenvs/simfoni_env/lib/python3.7/site-packages/rest_framework/views.py", line 469, in handle_exception
    self.raise_uncaught_exception(exc)
  File "/home/sandeep/.local/share/virtualenvs/simfoni_env/lib/python3.7/site-packages/rest_framework/views.py", line 480, in raise_uncaught_exception
    raise exc
  File "/home/sandeep/.local/share/virtualenvs/simfoni_env/lib/python3.7/site-packages/rest_framework/views.py", line 506, in dispatch
    response = handler(request, *args, **kwargs)
  File "/home/sandeep/.local/share/virtualenvs/simfoni_env/lib/python3.7/site-packages/rest_framework/generics.py", line 190, in post
    return self.create(request, *args, **kwargs)
  File "/home/sandeep/.local/share/virtualenvs/simfoni_env/lib/python3.7/site-packages/rest_framework/mixins.py", line 19, in create
    self.perform_create(serializer)
  File "/home/sandeep/.local/share/virtualenvs/simfoni_env/lib/python3.7/site-packages/rest_framework/mixins.py", line 24, in perform_create
    serializer.save()
  File "/home/sandeep/.local/share/virtualenvs/simfoni_env/lib/python3.7/site-packages/rest_framework/serializers.py", line 205, in save
    self.instance = self.create(validated_data)
  File "/home/sandeep/simfoni_task/suppliers/serializers.py", line 16, in create
    password = validated_data.pop("password")
KeyError: 'password'
"POST /api/suppliers/register/ HTTP/1.1" 500 117412
/home/sandeep/simfoni_task/suppliers/serializers.py changed, reloading.
Watching for file changes with StatReloader
Internal Server Error: /api/suppliers/register/
Traceback (most recent call last):
  File "/home/sandeep/.local/share/virtualenvs/simfoni_env/lib/python3.7/site-packages/django/core/handlers/exception.py", line 47, in inner
    response = get_response(request)
  File "/home/sandeep/.local/share/virtualenvs/simfoni_env/lib/python3.7/site-packages/django/core/handlers/base.py", line 181, in _get_response
    response = wrapped_callback(request, *callback_args, **callback_kwargs)
  File "/home/sandeep/.local/share/virtualenvs/simfoni_env/lib/python3.7/site-packages/django/views/decorators/csrf.py", line 54, in wrapped_view
    return view_func(*args, **kwargs)
  File "/home/sandeep/.local/share/virtualenvs/simfoni_env/lib/python3.7/site-packages/django/views/generic/base.py", line 70, in view
    return self.dispatch(request, *args, **kwargs)
  File "/home/sandeep/.local/share/virtualenvs/simfoni_env/lib/python3.7/site-packages/rest_framework/views.py", line 509, in dispatch
    response = self.handle_exception(exc)
  File "/home/sandeep/.local/share/virtualenvs/simfoni_env/lib/python3.7/site-packages/rest_framework/views.py", line 469, in handle_exception
    self.raise_uncaught_exception(exc)
  File "/home/sandeep/.local/share/virtualenvs/simfoni_env/lib/python3.7/site-packages/rest_framework/views.py", line 480, in raise_uncaught_exception
    raise exc
  File "/home/sandeep/.local/share/virtualenvs/simfoni_env/lib/python3.7/site-packages/rest_framework/views.py", line 506, in dispatch
    response = handler(request, *args, **kwargs)
  File "/home/sandeep/.local/share/virtualenvs/simfoni_env/lib/python3.7/site-packages/rest_framework/generics.py", line 190, in post
    return self.create(request, *args, **kwargs)
  File "/home/sandeep/.local/share/virtualenvs/simfoni_env/lib/python3.7/site-packages/rest_framework/mixins.py", line 19, in create
    self.perform_create(serializer)
  File "/home/sandeep/.local/share/virtualenvs/simfoni_env/lib/python3.7/site-packages/rest_framework/mixins.py", line 24, in perform_create
    serializer.save()
  File "/home/sandeep/.local/share/virtualenvs/simfoni_env/lib/python3.7/site-packages/rest_framework/serializers.py", line 205, in save
    self.instance = self.create(validated_data)
  File "/home/sandeep/simfoni_task/suppliers/serializers.py", line 16, in create
    password = validated_data.pop("password")
KeyError: 'password'
"POST /api/suppliers/register/ HTTP/1.1" 500 117426
/home/sandeep/simfoni_task/suppliers/serializers.py changed, reloading.
Watching for file changes with StatReloader
/home/sandeep/simfoni_task/suppliers/serializers.py changed, reloading.
Watching for file changes with StatReloader
Internal Server Error: /api/suppliers/register/
Traceback (most recent call last):
  File "/home/sandeep/.local/share/virtualenvs/simfoni_env/lib/python3.7/site-packages/django/core/handlers/exception.py", line 47, in inner
    response = get_response(request)
  File "/home/sandeep/.local/share/virtualenvs/simfoni_env/lib/python3.7/site-packages/django/core/handlers/base.py", line 181, in _get_response
    response = wrapped_callback(request, *callback_args, **callback_kwargs)
  File "/home/sandeep/.local/share/virtualenvs/simfoni_env/lib/python3.7/site-packages/django/views/decorators/csrf.py", line 54, in wrapped_view
    return view_func(*args, **kwargs)
  File "/home/sandeep/.local/share/virtualenvs/simfoni_env/lib/python3.7/site-packages/django/views/generic/base.py", line 70, in view
    return self.dispatch(request, *args, **kwargs)
  File "/home/sandeep/.local/share/virtualenvs/simfoni_env/lib/python3.7/site-packages/rest_framework/views.py", line 509, in dispatch
    response = self.handle_exception(exc)
  File "/home/sandeep/.local/share/virtualenvs/simfoni_env/lib/python3.7/site-packages/rest_framework/views.py", line 469, in handle_exception
    self.raise_uncaught_exception(exc)
  File "/home/sandeep/.local/share/virtualenvs/simfoni_env/lib/python3.7/site-packages/rest_framework/views.py", line 480, in raise_uncaught_exception
    raise exc
  File "/home/sandeep/.local/share/virtualenvs/simfoni_env/lib/python3.7/site-packages/rest_framework/views.py", line 506, in dispatch
    response = handler(request, *args, **kwargs)
  File "/home/sandeep/.local/share/virtualenvs/simfoni_env/lib/python3.7/site-packages/rest_framework/generics.py", line 190, in post
    return self.create(request, *args, **kwargs)
  File "/home/sandeep/.local/share/virtualenvs/simfoni_env/lib/python3.7/site-packages/rest_framework/mixins.py", line 19, in create
    self.perform_create(serializer)
  File "/home/sandeep/.local/share/virtualenvs/simfoni_env/lib/python3.7/site-packages/rest_framework/mixins.py", line 24, in perform_create
    serializer.save()
  File "/home/sandeep/.local/share/virtualenvs/simfoni_env/lib/python3.7/site-packages/rest_framework/serializers.py", line 205, in save
    self.instance = self.create(validated_data)
  File "/home/sandeep/simfoni_task/suppliers/serializers.py", line 16, in create
    password = validated_data.pop("password")
KeyError: 'password'
"POST /api/suppliers/register/ HTTP/1.1" 500 117452
/home/sandeep/simfoni_task/suppliers/serializers.py changed, reloading.
Watching for file changes with StatReloader
Internal Server Error: /api/suppliers/register/
Traceback (most recent call last):
  File "/home/sandeep/.local/share/virtualenvs/simfoni_env/lib/python3.7/site-packages/django/core/handlers/exception.py", line 47, in inner
    response = get_response(request)
  File "/home/sandeep/.local/share/virtualenvs/simfoni_env/lib/python3.7/site-packages/django/core/handlers/base.py", line 181, in _get_response
    response = wrapped_callback(request, *callback_args, **callback_kwargs)
  File "/home/sandeep/.local/share/virtualenvs/simfoni_env/lib/python3.7/site-packages/django/views/decorators/csrf.py", line 54, in wrapped_view
    return view_func(*args, **kwargs)
  File "/home/sandeep/.local/share/virtualenvs/simfoni_env/lib/python3.7/site-packages/django/views/generic/base.py", line 70, in view
    return self.dispatch(request, *args, **kwargs)
  File "/home/sandeep/.local/share/virtualenvs/simfoni_env/lib/python3.7/site-packages/rest_framework/views.py", line 509, in dispatch
    response = self.handle_exception(exc)
  File "/home/sandeep/.local/share/virtualenvs/simfoni_env/lib/python3.7/site-packages/rest_framework/views.py", line 469, in handle_exception
    self.raise_uncaught_exception(exc)
  File "/home/sandeep/.local/share/virtualenvs/simfoni_env/lib/python3.7/site-packages/rest_framework/views.py", line 480, in raise_uncaught_exception
    raise exc
  File "/home/sandeep/.local/share/virtualenvs/simfoni_env/lib/python3.7/site-packages/rest_framework/views.py", line 506, in dispatch
    response = handler(request, *args, **kwargs)
  File "/home/sandeep/.local/share/virtualenvs/simfoni_env/lib/python3.7/site-packages/rest_framework/generics.py", line 190, in post
    return self.create(request, *args, **kwargs)
  File "/home/sandeep/.local/share/virtualenvs/simfoni_env/lib/python3.7/site-packages/rest_framework/mixins.py", line 19, in create
    self.perform_create(serializer)
  File "/home/sandeep/.local/share/virtualenvs/simfoni_env/lib/python3.7/site-packages/rest_framework/mixins.py", line 24, in perform_create
    serializer.save()
  File "/home/sandeep/.local/share/virtualenvs/simfoni_env/lib/python3.7/site-packages/rest_framework/serializers.py", line 205, in save
    self.instance = self.create(validated_data)
  File "/home/sandeep/simfoni_task/suppliers/serializers.py", line 16, in create
    password = validated_data.pop("password")
KeyError: 'password'
"POST /api/suppliers/register/ HTTP/1.1" 500 117474
/home/sandeep/simfoni_task/suppliers/serializers.py changed, reloading.
Watching for file changes with StatReloader
/home/sandeep/simfoni_task/suppliers/serializers.py changed, reloading.
Watching for file changes with StatReloader
Internal Server Error: /api/suppliers/register/
Traceback (most recent call last):
  File "/home/sandeep/.local/share/virtualenvs/simfoni_env/lib/python3.7/site-packages/django/core/handlers/exception.py", line 47, in inner
    response = get_response(request)
  File "/home/sandeep/.local/share/virtualenvs/simfoni_env/lib/python3.7/site-packages/django/core/handlers/base.py", line 181, in _get_response
    response = wrapped_callback(request, *callback_args, **callback_kwargs)
  File "/home/sandeep/.local/share/virtualenvs/simfoni_env/lib/python3.7/site-packages/django/views/decorators/csrf.py", line 54, in wrapped_view
    return view_func(*args, **kwargs)
  File "/home/sandeep/.local/share/virtualenvs/simfoni_env/lib/python3.7/site-packages/django/views/generic/base.py", line 70, in view
    return self.dispatch(request, *args, **kwargs)
  File "/home/sandeep/.local/share/virtualenvs/simfoni_env/lib/python3.7/site-packages/rest_framework/views.py", line 509, in dispatch
    response = self.handle_exception(exc)
  File "/home/sandeep/.local/share/virtualenvs/simfoni_env/lib/python3.7/site-packages/rest_framework/views.py", line 469, in handle_exception
    self.raise_uncaught_exception(exc)
  File "/home/sandeep/.local/share/virtualenvs/simfoni_env/lib/python3.7/site-packages/rest_framework/views.py", line 480, in raise_uncaught_exception
    raise exc
  File "/home/sandeep/.local/share/virtualenvs/simfoni_env/lib/python3.7/site-packages/rest_framework/views.py", line 506, in dispatch
    response = handler(request, *args, **kwargs)
  File "/home/sandeep/.local/share/virtualenvs/simfoni_env/lib/python3.7/site-packages/rest_framework/generics.py", line 190, in post
    return self.create(request, *args, **kwargs)
  File "/home/sandeep/.local/share/virtualenvs/simfoni_env/lib/python3.7/site-packages/rest_framework/mixins.py", line 19, in create
    self.perform_create(serializer)
  File "/home/sandeep/.local/share/virtualenvs/simfoni_env/lib/python3.7/site-packages/rest_framework/mixins.py", line 24, in perform_create
    serializer.save()
  File "/home/sandeep/.local/share/virtualenvs/simfoni_env/lib/python3.7/site-packages/rest_framework/serializers.py", line 205, in save
    self.instance = self.create(validated_data)
  File "/home/sandeep/simfoni_task/suppliers/serializers.py", line 19, in create
    return Supplier.objects.create(**validated_data)
  File "/home/sandeep/.local/share/virtualenvs/simfoni_env/lib/python3.7/site-packages/django/db/models/manager.py", line 85, in manager_method
    return getattr(self.get_queryset(), name)(*args, **kwargs)
  File "/home/sandeep/.local/share/virtualenvs/simfoni_env/lib/python3.7/site-packages/django/db/models/query.py", line 445, in create
    obj = self.model(**kwargs)
  File "/home/sandeep/.local/share/virtualenvs/simfoni_env/lib/python3.7/site-packages/django/db/models/base.py", line 483, in __init__
    _setattr(self, field.name, rel_obj)
  File "/home/sandeep/.local/share/virtualenvs/simfoni_env/lib/python3.7/site-packages/django/db/models/fields/related_descriptors.py", line 220, in __set__
    self.field.remote_field.model._meta.object_name,
ValueError: Cannot assign "5": "Supplier.auth_user" must be a "User" instance.
"POST /api/suppliers/register/ HTTP/1.1" 500 137519
/home/sandeep/simfoni_task/suppliers/serializers.py changed, reloading.
Watching for file changes with StatReloader
Internal Server Error: /api/suppliers/register/
Traceback (most recent call last):
  File "/home/sandeep/.local/share/virtualenvs/simfoni_env/lib/python3.7/site-packages/django/db/backends/utils.py", line 84, in _execute
    return self.cursor.execute(sql, params)
psycopg2.errors.UniqueViolation: duplicate key value violates unique constraint "auth_user_username_key"
DETAIL:  Key (username)=(sandeep3@gmail.com) already exists.


The above exception was the direct cause of the following exception:

Traceback (most recent call last):
  File "/home/sandeep/.local/share/virtualenvs/simfoni_env/lib/python3.7/site-packages/django/core/handlers/exception.py", line 47, in inner
    response = get_response(request)
  File "/home/sandeep/.local/share/virtualenvs/simfoni_env/lib/python3.7/site-packages/django/core/handlers/base.py", line 181, in _get_response
    response = wrapped_callback(request, *callback_args, **callback_kwargs)
  File "/home/sandeep/.local/share/virtualenvs/simfoni_env/lib/python3.7/site-packages/django/views/decorators/csrf.py", line 54, in wrapped_view
    return view_func(*args, **kwargs)
  File "/home/sandeep/.local/share/virtualenvs/simfoni_env/lib/python3.7/site-packages/django/views/generic/base.py", line 70, in view
    return self.dispatch(request, *args, **kwargs)
  File "/home/sandeep/.local/share/virtualenvs/simfoni_env/lib/python3.7/site-packages/rest_framework/views.py", line 509, in dispatch
    response = self.handle_exception(exc)
  File "/home/sandeep/.local/share/virtualenvs/simfoni_env/lib/python3.7/site-packages/rest_framework/views.py", line 469, in handle_exception
    self.raise_uncaught_exception(exc)
  File "/home/sandeep/.local/share/virtualenvs/simfoni_env/lib/python3.7/site-packages/rest_framework/views.py", line 480, in raise_uncaught_exception
    raise exc
  File "/home/sandeep/.local/share/virtualenvs/simfoni_env/lib/python3.7/site-packages/rest_framework/views.py", line 506, in dispatch
    response = handler(request, *args, **kwargs)
  File "/home/sandeep/.local/share/virtualenvs/simfoni_env/lib/python3.7/site-packages/rest_framework/generics.py", line 190, in post
    return self.create(request, *args, **kwargs)
  File "/home/sandeep/.local/share/virtualenvs/simfoni_env/lib/python3.7/site-packages/rest_framework/mixins.py", line 19, in create
    self.perform_create(serializer)
  File "/home/sandeep/.local/share/virtualenvs/simfoni_env/lib/python3.7/site-packages/rest_framework/mixins.py", line 24, in perform_create
    serializer.save()
  File "/home/sandeep/.local/share/virtualenvs/simfoni_env/lib/python3.7/site-packages/rest_framework/serializers.py", line 205, in save
    self.instance = self.create(validated_data)
  File "/home/sandeep/simfoni_task/suppliers/serializers.py", line 16, in create
    user = User.objects.create_user(username=username, password=password)
  File "/home/sandeep/.local/share/virtualenvs/simfoni_env/lib/python3.7/site-packages/django/contrib/auth/models.py", line 146, in create_user
    return self._create_user(username, email, password, **extra_fields)
  File "/home/sandeep/.local/share/virtualenvs/simfoni_env/lib/python3.7/site-packages/django/contrib/auth/models.py", line 140, in _create_user
    user.save(using=self._db)
  File "/home/sandeep/.local/share/virtualenvs/simfoni_env/lib/python3.7/site-packages/django/contrib/auth/base_user.py", line 67, in save
    super().save(*args, **kwargs)
  File "/home/sandeep/.local/share/virtualenvs/simfoni_env/lib/python3.7/site-packages/django/db/models/base.py", line 754, in save
    force_update=force_update, update_fields=update_fields)
  File "/home/sandeep/.local/share/virtualenvs/simfoni_env/lib/python3.7/site-packages/django/db/models/base.py", line 792, in save_base
    force_update, using, update_fields,
  File "/home/sandeep/.local/share/virtualenvs/simfoni_env/lib/python3.7/site-packages/django/db/models/base.py", line 895, in _save_table
    results = self._do_insert(cls._base_manager, using, fields, returning_fields, raw)
  File "/home/sandeep/.local/share/virtualenvs/simfoni_env/lib/python3.7/site-packages/django/db/models/base.py", line 935, in _do_insert
    using=using, raw=raw,
  File "/home/sandeep/.local/share/virtualenvs/simfoni_env/lib/python3.7/site-packages/django/db/models/manager.py", line 85, in manager_method
    return getattr(self.get_queryset(), name)(*args, **kwargs)
  File "/home/sandeep/.local/share/virtualenvs/simfoni_env/lib/python3.7/site-packages/django/db/models/query.py", line 1254, in _insert
    return query.get_compiler(using=using).execute_sql(returning_fields)
  File "/home/sandeep/.local/share/virtualenvs/simfoni_env/lib/python3.7/site-packages/django/db/models/sql/compiler.py", line 1397, in execute_sql
    cursor.execute(sql, params)
  File "/home/sandeep/.local/share/virtualenvs/simfoni_env/lib/python3.7/site-packages/django/db/backends/utils.py", line 98, in execute
    return super().execute(sql, params)
  File "/home/sandeep/.local/share/virtualenvs/simfoni_env/lib/python3.7/site-packages/django/db/backends/utils.py", line 66, in execute
    return self._execute_with_wrappers(sql, params, many=False, executor=self._execute)
  File "/home/sandeep/.local/share/virtualenvs/simfoni_env/lib/python3.7/site-packages/django/db/backends/utils.py", line 75, in _execute_with_wrappers
    return executor(sql, params, many, context)
  File "/home/sandeep/.local/share/virtualenvs/simfoni_env/lib/python3.7/site-packages/django/db/backends/utils.py", line 84, in _execute
    return self.cursor.execute(sql, params)
  File "/home/sandeep/.local/share/virtualenvs/simfoni_env/lib/python3.7/site-packages/django/db/utils.py", line 90, in __exit__
    raise dj_exc_value.with_traceback(traceback) from exc_value
  File "/home/sandeep/.local/share/virtualenvs/simfoni_env/lib/python3.7/site-packages/django/db/backends/utils.py", line 84, in _execute
    return self.cursor.execute(sql, params)
django.db.utils.IntegrityError: duplicate key value violates unique constraint "auth_user_username_key"
DETAIL:  Key (username)=(sandeep3@gmail.com) already exists.

"POST /api/suppliers/register/ HTTP/1.1" 500 209638
"POST /api/suppliers/register/ HTTP/1.1" 201 110
/home/sandeep/simfoni_task/suppliers/serializers.py changed, reloading.
Watching for file changes with StatReloader
/home/sandeep/simfoni_task/suppliers/serializers.py changed, reloading.
Watching for file changes with StatReloader
/home/sandeep/simfoni_task/suppliers/serializers.py changed, reloading.
Watching for file changes with StatReloader
/home/sandeep/simfoni_task/suppliers/serializers.py changed, reloading.
Watching for file changes with StatReloader
/home/sandeep/simfoni_task/suppliers/serializers.py changed, reloading.
Watching for file changes with StatReloader
Internal Server Error: /api/suppliers/register/
Traceback (most recent call last):
  File "/home/sandeep/simfoni_task/suppliers/serializers.py", line 19, in create
    validators.validate_password(password=password, user=User)
  File "/home/sandeep/.local/share/virtualenvs/simfoni_env/lib/python3.7/site-packages/django/contrib/auth/password_validation.py", line 51, in validate_password
    raise ValidationError(errors)
django.core.exceptions.ValidationError: ['The password must contain at least 1 uppercase letter, A-Z.']

During handling of the above exception, another exception occurred:

Traceback (most recent call last):
  File "/home/sandeep/.local/share/virtualenvs/simfoni_env/lib/python3.7/site-packages/django/core/handlers/exception.py", line 47, in inner
    response = get_response(request)
  File "/home/sandeep/.local/share/virtualenvs/simfoni_env/lib/python3.7/site-packages/django/core/handlers/base.py", line 181, in _get_response
    response = wrapped_callback(request, *callback_args, **callback_kwargs)
  File "/home/sandeep/.local/share/virtualenvs/simfoni_env/lib/python3.7/site-packages/django/views/decorators/csrf.py", line 54, in wrapped_view
    return view_func(*args, **kwargs)
  File "/home/sandeep/.local/share/virtualenvs/simfoni_env/lib/python3.7/site-packages/django/views/generic/base.py", line 70, in view
    return self.dispatch(request, *args, **kwargs)
  File "/home/sandeep/.local/share/virtualenvs/simfoni_env/lib/python3.7/site-packages/rest_framework/views.py", line 509, in dispatch
    response = self.handle_exception(exc)
  File "/home/sandeep/.local/share/virtualenvs/simfoni_env/lib/python3.7/site-packages/rest_framework/views.py", line 469, in handle_exception
    self.raise_uncaught_exception(exc)
  File "/home/sandeep/.local/share/virtualenvs/simfoni_env/lib/python3.7/site-packages/rest_framework/views.py", line 480, in raise_uncaught_exception
    raise exc
  File "/home/sandeep/.local/share/virtualenvs/simfoni_env/lib/python3.7/site-packages/rest_framework/views.py", line 506, in dispatch
    response = handler(request, *args, **kwargs)
  File "/home/sandeep/.local/share/virtualenvs/simfoni_env/lib/python3.7/site-packages/rest_framework/generics.py", line 190, in post
    return self.create(request, *args, **kwargs)
  File "/home/sandeep/.local/share/virtualenvs/simfoni_env/lib/python3.7/site-packages/rest_framework/mixins.py", line 19, in create
    self.perform_create(serializer)
  File "/home/sandeep/.local/share/virtualenvs/simfoni_env/lib/python3.7/site-packages/rest_framework/mixins.py", line 24, in perform_create
    serializer.save()
  File "/home/sandeep/.local/share/virtualenvs/simfoni_env/lib/python3.7/site-packages/rest_framework/serializers.py", line 205, in save
    self.instance = self.create(validated_data)
  File "/home/sandeep/simfoni_task/suppliers/serializers.py", line 21, in create
    raise serializers.ValidationError(e.message)
AttributeError: 'ValidationError' object has no attribute 'message'
"POST /api/suppliers/register/ HTTP/1.1" 500 128934
/home/sandeep/simfoni_task/suppliers/serializers.py changed, reloading.
Watching for file changes with StatReloader
Bad Request: /api/suppliers/register/
"POST /api/suppliers/register/ HTTP/1.1" 400 67
Bad Request: /api/suppliers/register/
"POST /api/suppliers/register/ HTTP/1.1" 400 161
Bad Request: /api/suppliers/register/
"POST /api/suppliers/register/ HTTP/1.1" 400 91
Bad Request: /api/suppliers/register/
"POST /api/suppliers/register/ HTTP/1.1" 400 67
"POST /api/suppliers/register/ HTTP/1.1" 201 110
Bad Request: /api/suppliers/register/
"POST /api/suppliers/register/ HTTP/1.1" 400 70
"POST /api/suppliers/register/ HTTP/1.1" 201 117
Bad Request: /api/suppliers/register/
"POST /api/suppliers/register/ HTTP/1.1" 400 70
/home/sandeep/simfoni_task/suppliers/serializers.py changed, reloading.
Watching for file changes with StatReloader
Not Acceptable: /api/suppliers/login/
"POST /api/suppliers/login/ HTTP/1.1" 406 59
/home/sandeep/simfoni_task/suppliers/views.py changed, reloading.
Watching for file changes with StatReloader
Internal Server Error: /api/suppliers/login/
Traceback (most recent call last):
  File "/home/sandeep/.local/share/virtualenvs/simfoni_env/lib/python3.7/site-packages/django/core/handlers/exception.py", line 47, in inner
    response = get_response(request)
  File "/home/sandeep/.local/share/virtualenvs/simfoni_env/lib/python3.7/site-packages/django/core/handlers/base.py", line 204, in _get_response
    response = response.render()
  File "/home/sandeep/.local/share/virtualenvs/simfoni_env/lib/python3.7/site-packages/django/template/response.py", line 105, in render
    self.content = self.rendered_content
  File "/home/sandeep/.local/share/virtualenvs/simfoni_env/lib/python3.7/site-packages/rest_framework/response.py", line 70, in rendered_content
    ret = renderer.render(self.data, accepted_media_type, context)
  File "/home/sandeep/.local/share/virtualenvs/simfoni_env/lib/python3.7/site-packages/rest_framework/renderers.py", line 103, in render
    allow_nan=not self.strict, separators=separators
  File "/home/sandeep/.local/share/virtualenvs/simfoni_env/lib/python3.7/site-packages/rest_framework/utils/json.py", line 25, in dumps
    return json.dumps(*args, **kwargs)
  File "/usr/lib/python3.7/json/__init__.py", line 238, in dumps
    **kw).encode(obj)
  File "/usr/lib/python3.7/json/encoder.py", line 199, in encode
    chunks = self.iterencode(o, _one_shot=True)
  File "/usr/lib/python3.7/json/encoder.py", line 257, in iterencode
    return _iterencode(o, 0)
  File "/home/sandeep/.local/share/virtualenvs/simfoni_env/lib/python3.7/site-packages/rest_framework/utils/encoders.py", line 67, in default
    return super().default(obj)
  File "/usr/lib/python3.7/json/encoder.py", line 179, in default
    raise TypeError(f'Object of type {o.__class__.__name__} '
TypeError: Object of type RelatedManager is not JSON serializable
"POST /api/suppliers/login/ HTTP/1.1" 500 110479
/home/sandeep/simfoni_task/suppliers/views.py changed, reloading.
Watching for file changes with StatReloader
Not Acceptable: /api/suppliers/login/
"POST /api/suppliers/login/ HTTP/1.1" 406 59
/home/sandeep/simfoni_task/suppliers/views.py changed, reloading.
Watching for file changes with StatReloader
"POST /api/suppliers/login/ HTTP/1.1" 200 453
/home/sandeep/simfoni_task/suppliers/views.py changed, reloading.
Watching for file changes with StatReloader
/home/sandeep/simfoni_task/suppliers/views.py changed, reloading.
Watching for file changes with StatReloader
/home/sandeep/simfoni_task/suppliers/views.py changed, reloading.
Watching for file changes with StatReloader
/home/sandeep/simfoni_task/suppliers/urls.py changed, reloading.
Watching for file changes with StatReloader
"GET /api/suppliers/4/ HTTP/1.1" 200 356
/home/sandeep/simfoni_task/suppliers/serializers.py changed, reloading.
Watching for file changes with StatReloader
/home/sandeep/simfoni_task/suppliers/serializers.py changed, reloading.
Watching for file changes with StatReloader
"GET /api/suppliers/4/ HTTP/1.1" 200 378
/home/sandeep/simfoni_task/suppliers/admin.py changed, reloading.
Watching for file changes with StatReloader
"GET /admin HTTP/1.1" 301 0
"GET /admin/ HTTP/1.1" 302 0
"GET /admin/login/?next=/admin/ HTTP/1.1" 200 2194
"GET /static/admin/css/login.css HTTP/1.1" 200 1185
"GET /static/admin/css/nav_sidebar.css HTTP/1.1" 200 2138
"GET /static/admin/css/responsive.css HTTP/1.1" 200 18339
"GET /static/admin/js/nav_sidebar.js HTTP/1.1" 200 1360
Watching for file changes with StatReloader
"POST /admin/login/?next=/admin/ HTTP/1.1" 302 0
"GET /admin/ HTTP/1.1" 200 5603
"GET /admin/suppliers/product/ HTTP/1.1" 200 6152
"GET /admin/jsi18n/ HTTP/1.1" 200 3187
"GET /admin/suppliers/product/add/ HTTP/1.1" 200 8885
"GET /admin/jsi18n/ HTTP/1.1" 200 3187
"POST /admin/suppliers/product/add/ HTTP/1.1" 302 0
"GET /admin/suppliers/product/ HTTP/1.1" 200 7507
"GET /admin/jsi18n/ HTTP/1.1" 200 3187
"GET /api/suppliers/4/ HTTP/1.1" 200 378
"GET /api/suppliers/5/ HTTP/1.1" 200 385
"GET /api/suppliers/3/ HTTP/1.1" 200 521
"GET /admin/suppliers/product/add/ HTTP/1.1" 200 8885
"GET /admin/suppliers/product/ HTTP/1.1" 200 7305
"GET /admin/ HTTP/1.1" 200 5924
"GET /admin/login/?next=/admin/ HTTP/1.1" 302 0
"GET /admin/ HTTP/1.1" 200 5924
"GET / HTTP/1.1" 200 2236
/home/sandeep/simfoni_task/suppliers/urls.py changed, reloading.
Watching for file changes with StatReloader
/home/sandeep/simfoni_task/suppliers/urls.py changed, reloading.
Watching for file changes with StatReloader
"GET /api/suppliers/ HTTP/1.1" 200 613
/home/sandeep/simfoni_task/suppliers/views.py changed, reloading.
Watching for file changes with StatReloader
"GET /api/suppliers/ HTTP/1.1" 200 2096
/home/sandeep/simfoni_task/suppliers/serializers.py changed, reloading.
Watching for file changes with StatReloader
/home/sandeep/simfoni_task/suppliers/serializers.py changed, reloading.
Watching for file changes with StatReloader
/home/sandeep/simfoni_task/suppliers/serializers.py changed, reloading.
Watching for file changes with StatReloader
/home/sandeep/simfoni_task/suppliers/serializers.py changed, reloading.
Watching for file changes with StatReloader
/home/sandeep/simfoni_task/suppliers/views.py changed, reloading.
Watching for file changes with StatReloader
/home/sandeep/simfoni_task/suppliers/views.py changed, reloading.
Watching for file changes with StatReloader
/home/sandeep/simfoni_task/suppliers/urls.py changed, reloading.
Watching for file changes with StatReloader
/home/sandeep/simfoni_task/suppliers/urls.py changed, reloading.
Watching for file changes with StatReloader
/home/sandeep/simfoni_task/suppliers/urls.py changed, reloading.
Watching for file changes with StatReloader
Internal Server Error: /api/suppliers/update/4
Traceback (most recent call last):
  File "/home/sandeep/.local/share/virtualenvs/simfoni_env/lib/python3.7/site-packages/django/core/handlers/exception.py", line 47, in inner
    response = get_response(request)
  File "/home/sandeep/.local/share/virtualenvs/simfoni_env/lib/python3.7/site-packages/django/utils/deprecation.py", line 113, in __call__
    response = self.process_request(request)
  File "/home/sandeep/.local/share/virtualenvs/simfoni_env/lib/python3.7/site-packages/django/middleware/common.py", line 54, in process_request
    path = self.get_full_path_with_slash(request)
  File "/home/sandeep/.local/share/virtualenvs/simfoni_env/lib/python3.7/site-packages/django/middleware/common.py", line 94, in get_full_path_with_slash
    'url': request.get_host() + new_path,
RuntimeError: You called this URL via POST, but the URL doesn't end in a slash and you have APPEND_SLASH set. Django can't redirect to the slash URL while maintaining POST data. Change your form to point to 127.0.0.1:8000/api/suppliers/update/4/ (note the trailing slash), or set APPEND_SLASH=False in your Django settings.
"POST /api/suppliers/update/4 HTTP/1.1" 500 76149
Method Not Allowed: /api/suppliers/update/4/
"POST /api/suppliers/update/4/ HTTP/1.1" 405 41
"PATCH /api/suppliers/update/4/ HTTP/1.1" 200 364
